Workbook

Sheet Таблица
A1: =IMAGE("https://raw.githubusercontent.com/RedCat161/AoM/main/Runes/Rune.jpg") | M1: совпадения | N1: by RedCat#1BVV
N2: Сперва вбиваем Созвездие артефакта при помощи буквенного выпадающего меню!! Далее для сортировки по совпадениям, жмем ➟ | Q2: =IMAGE("https://raw.githubusercontent.com/RedCat161/AoM/main/photo_2026-01-11_22-35-59.jpg") | S2: 2-й навык Артуса и 3-й навык Дэнайи дают возможность совершать контратаки абсолютно всем персонажам
B3: =IMAGE("https://raw.githubusercontent.com/RedCat161/AoM/main/RedCat_200.jpg") | C3: Артефакт | E3: L | G3: G | I3: E | K3: B | N3: Массовая атака | P3: Контратака
E4: =VLOOKUP(E3,'Созвездия'!A:B,2,FALSE) | G4: =VLOOKUP(G3,'Созвездия'!A:B,2,FALSE) | I4: =VLOOKUP(I3,'Созвездия'!A:B,2,FALSE) | K4: =VLOOKUP(K3,'Созвездия'!A:B,2,FALSE) | N4: Одиночная атака | P4: Вспомогательная атака
A5: № | B5: Фракция | C5: Персонаж | E5: Созвездие | N5: Навык 1 | O5: Навык 2 | P5: Навык 3 | Q5: Навык 4 | R5: Контратака | S5: Контратака за счет другого перса | T5: Вспомогательная Атака | U5: Вспомогательная за счет другого перса
A6: 1 | B6: Фатуриши | C6: Сарпани | D6: =IMAGE("https://raw.githubusercontent.com/RedCat161/AoM/main/fat/fat2_200.jpg") | E6: ='Созвездия'!B4 | F6: C | G6: ='Созвездия'!B4 | H6: C | I6: ='Созвездия'!B6 | J6: E | K6: ='Созвездия'!B6 | L6: E | M6: =SUM( MAP( UNIQUE({$E$3;$G$3;$I$3;$K$3}), LAMBDA(x, MIN( COUNTIF({$E$3;$G$3;$I$3;$K$3}, x), COUNTIF({F6;H6;J6;L6}, x) ) ) ) ) -> 1
A7: 2 | B7: Фатуриши | C7: Вирашан | D7: =IMAGE("https://raw.githubusercontent.com/RedCat161/AoM/main/fat/fat3_200.jpg") | E7: ='Созвездия'!B9 | F7: H | G7: ='Созвездия'!B4 | H7: C | I7: ='Созвездия'!B7 | J7: F | K7: ='Созвездия'!B6 | L7: E | M7: =SUM( MAP( UNIQUE({$E$3;$G$3;$I$3;$K$3}), LAMBDA(x, MIN( COUNTIF({$E$3;$G$3;$I$3;$K$3}, x), COUNTIF({F7;H7;J7;L7}, x) ) ) ) ) -> 1 | N7: Мульти
A8: 3 | B8: Фатуриши | C8: Сандхвар | D8: =IMAGE("https://raw.githubusercontent.com/RedCat161/AoM/main/fat/fat4_200.jpg") | E8: ='Созвездия'!B13 | F8: L | G8: ='Созвездия'!B13 | H8: L | I8: ='Созвездия'!B13 | J8: L | K8: ='Созвездия'!B4 | L8: C | M8: =SUM( MAP( UNIQUE({$E$3;$G$3;$I$3;$K$3}), LAMBDA(x, MIN( COUNTIF({$E$3;$G$3;$I$3;$K$3}, x), COUNTIF({F8;H8;J8;L8}, x) ) ) ) ) -> 1
A9: 4 | B9: Фатуриши | C9: Лакшайн | D9: =IMAGE("https://raw.githubusercontent.com/RedCat161/AoM/main/fat/fat1_200.jpg") | E9: ='Созвездия'!B9 | F9: H | G9: ='Созвездия'!B5 | H9: D | I9: ='Созвездия'!B7 | J9: F | K9: ='Созвездия'!B6 | L9: E | M9: =SUM( MAP( UNIQUE({$E$3;$G$3;$I$3;$K$3}), LAMBDA(x, MIN( COUNTIF({$E$3;$G$3;$I$3;$K$3}, x), COUNTIF({F9;H9;J9;L9}, x) ) ) ) ) -> 1 | O9: Мульти
A10: 5 | B10: Фатуриши | C10: Матави | D10: =IMAGE("https://raw.githubusercontent.com/RedCat161/AoM/main/fat/fat6_200.jpg") | E10: ='Созвездия'!B12 | F10: K | G10: ='Созвездия'!B12 | H10: K | I10: ='Созвездия'!B7 | J10: F | K10: ='Созвездия'!B7 | L10: F | M10: =SUM( MAP( UNIQUE({$E$3;$G$3;$I$3;$K$3}), LAMBDA(x, MIN( COUNTIF({$E$3;$G$3;$I$3;$K$3}, x), COUNTIF({F10;H10;J10;L10}, x) ) ) ) ) -> 0
A11: 6 | B11: Фатуриши | C11: Шанат | D11: =IMAGE("https://raw.githubusercontent.com/RedCat161/AoM/main/fat/fat5_200.jpg") | E11: ='Созвездия'!B10 | F11: I | G11: ='Созвездия'!B6 | H11: E | I11: ='Созвездия'!B2 | J11: A | K11: ='Созвездия'!B9 | L11: H | M11: =SUM( MAP( UNIQUE({$E$3;$G$3;$I$3;$K$3}), LAMBDA(x, MIN( COUNTIF({$E$3;$G$3;$I$3;$K$3}, x), COUNTIF({F11;H11;J11;L11}, x) ) ) ) ) -> 1 | P11: Мульти | T11: 2-й навык
A12: 7 | B12: Проклятый Цирк | C12: Марлена | D12: =IMAGE("https://raw.githubusercontent.com/RedCat161/AoM/main/circus/circus3_200.jpg") | E12: ='Созвездия'!B9 | F12: H | G12: ='Созвездия'!B8 | H12: G | I12: ='Созвездия'!B6 | J12: E | K12: ='Созвездия'!B2 | L12: A | M12: =SUM( MAP( UNIQUE({$E$3;$G$3;$I$3;$K$3}), LAMBDA(x, MIN( COUNTIF({$E$3;$G$3;$I$3;$K$3}, x), COUNTIF({F12;H12;J12;L12}, x) ) ) ) ) -> 2 | N12: Мульти
A13: 8 | B13: Проклятый Цирк | C13: Пикки | D13: =IMAGE("https://raw.githubusercontent.com/RedCat161/AoM/main/circus/circus4_200.jpg") | E13: ='Созвездия'!B12 | F13: K | G13: ='Созвездия'!B6 | H13: E | I13: ='Созвездия'!B2 | J13: A | K13: ='Созвездия'!B12 | L13: K | M13: =SUM( MAP( UNIQUE({$E$3;$G$3;$I$3;$K$3}), LAMBDA(x, MIN( COUNTIF({$E$3;$G$3;$I$3;$K$3}, x), COUNTIF({F13;H13;J13;L13}, x) ) ) ) ) -> 1
A14: 9 | B14: Проклятый Цирк | C14: Жан Глёр | D14: =IMAGE("https://raw.githubusercontent.com/RedCat161/AoM/main/circus/circus1_200.jpg") | E14: ='Созвездия'!B9 | F14: H | G14: ='Созвездия'!B11 | H14: J | I14: ='Созвездия'!B3 | J14: B | K14: ='Созвездия'!B11 | L14: J | M14: =SUM( MAP( UNIQUE({$E$3;$G$3;$I$3;$K$3}), LAMBDA(x, MIN( COUNTIF({$E$3;$G$3;$I$3;$K$3}, x), COUNTIF({F14;H14;J14;L14}, x) ) ) ) ) -> 1 | N14: Мульти | P14: Мульти
A15: 10 | B15: Проклятый Цирк | C15: Гозо | D15: =IMAGE("https://raw.githubusercontent.com/RedCat161/AoM/main/circus/circus2_200.jpg") | E15: ='Созвездия'!B8 | F15: G | G15: ='Созвездия'!B8 | H15: G | I15: ='Созвездия'!B13 | J15: L | K15: ='Созвездия'!B13 | L15: L | M15: =SUM( MAP( UNIQUE({$E$3;$G$3;$I$3;$K$3}), LAMBDA(x, MIN( COUNTIF({$E$3;$G$3;$I$3;$K$3}, x), COUNTIF({F15;H15;J15;L15}, x) ) ) ) ) -> 2
A16: 11 | B16: Проклятый Цирк | C16: Оукли | D16: =IMAGE("https://raw.githubusercontent.com/RedCat161/AoM/main/circus/circus5_200.jpg") | E16: ='Созвездия'!B11 | F16: J | G16: ='Созвездия'!B8 | H16: G | I16: ='Созвездия'!B6 | J16: E | K16: ='Созвездия'!B9 | L16: H | M16: =SUM( MAP( UNIQUE({$E$3;$G$3;$I$3;$K$3}), LAMBDA(x, MIN( COUNTIF({$E$3;$G$3;$I$3;$K$3}, x), COUNTIF({F16;H16;J16;L16}, x) ) ) ) ) -> 2 | O16: Мульти | R16: пассивка
A17: 12 | B17: Проклятый Цирк | C17: Серсела | D17: =IMAGE("https://raw.githubusercontent.com/RedCat161/AoM/main/circus/circus6_200.jpg") | E17: ='Созвездия'!B9 | F17: H | G17: ='Созвездия'!B6 | H17: E | I17: ='Созвездия'!B13 | J17: L | K17: ='Созвездия'!B8 | L17: G | M17: =SUM( MAP( UNIQUE({$E$3;$G$3;$I$3;$K$3}), LAMBDA(x, MIN( COUNTIF({$E$3;$G$3;$I$3;$K$3}, x), COUNTIF({F17;H17;J17;L17}, x) ) ) ) ) -> 3 | N17: Мульти | O17: Мульти
A18: 13 | B18: Алый Орден | C18: Тереза | D18: =IMAGE("https://raw.githubusercontent.com/RedCat161/AoM/main/Al/Al2_200.jpg") | E18: ='Созвездия'!B4 | F18: C | G18: ='Созвездия'!B4 | H18: C | I18: ='Созвездия'!B4 | J18: C | K18: ='Созвездия'!B8 | L18: G | M18: =SUM( MAP( UNIQUE({$E$3;$G$3;$I$3;$K$3}), LAMBDA(x, MIN( COUNTIF({$E$3;$G$3;$I$3;$K$3}, x), COUNTIF({F18;H18;J18;L18}, x) ) ) ) ) -> 1 | S18: 2-й навык Артуса | U18: С 1 пробуд Люца, база Бертрана
A19: 14 | B19: Алый Орден | C19: Люциус | D19: =IMAGE("https://raw.githubusercontent.com/RedCat161/AoM/main/Al/Al3_200.jpg") | E19: ='Созвездия'!B6 | F19: E | G19: ='Созвездия'!B6 | H19: E | I19: ='Созвездия'!B3 | J19: B | K19: ='Созвездия'!B2 | L19: A | M19: =SUM( MAP( UNIQUE({$E$3;$G$3;$I$3;$K$3}), LAMBDA(x, MIN( COUNTIF({$E$3;$G$3;$I$3;$K$3}, x), COUNTIF({F19;H19;J19;L19}, x) ) ) ) ) -> 2 | N19: Мульти | P19: Мульти | S19: 2-й навык Артуса | U19: база Бертрана
A20: 15 | B20: Алый Орден | C20: Бенедикт | D20: =IMAGE("https://raw.githubusercontent.com/RedCat161/AoM/main/Al/Al4_200.jpg") | E20: ='Созвездия'!B8 | F20: G | G20: ='Созвездия'!B8 | H20: G | I20: ='Созвездия'!B2 | J20: A | K20: ='Созвездия'!B2 | L20: A | M20: =SUM( MAP( UNIQUE({$E$3;$G$3;$I$3;$K$3}), LAMBDA(x, MIN( COUNTIF({$E$3;$G$3;$I$3;$K$3}, x), COUNTIF({F20;H20;J20;L20}, x) ) ) ) ) -> 1 | S20: 2-й навык Артуса | U20: С 1 пробуд Люца, база Бертрана
A21: 16 | B21: Алый Орден | C21: Мария | D21: =IMAGE("https://raw.githubusercontent.com/RedCat161/AoM/main/Al/Al5_200.jpg") | E21: ='Созвездия'!B6 | F21: E | G21: ='Созвездия'!B9 | H21: H | I21: ='Созвездия'!B3 | J21: B | K21: ='Созвездия'!B4 | L21: C | M21: =SUM( MAP( UNIQUE({$E$3;$G$3;$I$3;$K$3}), LAMBDA(x, MIN( COUNTIF({$E$3;$G$3;$I$3;$K$3}, x), COUNTIF({F21;H21;J21;L21}, x) ) ) ) ) -> 2 | S21: 2-й навык Артуса | U21: С 1 пробуд Люца, база Бертрана
A22: 17 | B22: Алый Орден | C22: Феликс | D22: =IMAGE("https://raw.githubusercontent.com/RedCat161/AoM/main/Al/Al1_200.jpg") | E22: ='Созвездия'!B9 | F22: H | G22: ='Созвездия'!B9 | H22: H | I22: ='Созвездия'!B6 | J22: E | K22: ='Созвездия'!B2 | L22: A | M22: =SUM( MAP( UNIQUE({$E$3;$G$3;$I$3;$K$3}), LAMBDA(x, MIN( COUNTIF({$E$3;$G$3;$I$3;$K$3}, x), COUNTIF({F22;H22;J22;L22}, x) ) ) ) ) -> 1 | P22: Мульти | S22: 2-й навык Артуса | U22: С 1 пробуд Люца, база Бертрана
A23: 18 | B23: Алый Орден | C23: Бертран | D23: =IMAGE("https://raw.githubusercontent.com/RedCat161/AoM/main/Al/Al6_200.jpg") | E23: ='Созвездия'!B6 | F23: E | G23: ='Созвездия'!B6 | H23: E | I23: ='Созвездия'!B6 | J23: E | K23: ='Созвездия'!B7 | L23: F | M23: =SUM( MAP( UNIQUE({$E$3;$G$3;$I$3;$K$3}), LAMBDA(x, MIN( COUNTIF({$E$3;$G$3;$I$3;$K$3}, x), COUNTIF({F23;H23;J23;L23}, x) ) ) ) ) -> 1 | S23: 2-й навык Артуса | U23: С 1 пробуд Люца
A24: 19 | B24: Алый Орден | C24: Агнесса | D24: =IMAGE("https://raw.githubusercontent.com/RedCat161/AoM/main/Al/Al7_200.jpg") | E24: ='Созвездия'!B9 | F24: H | G24: ='Созвездия'!B9 | H24: H | I24: ='Созвездия'!B9 | J24: H | K24: ='Созвездия'!B3 | L24: B | M24: =SUM( MAP( UNIQUE({$E$3;$G$3;$I$3;$K$3}), LAMBDA(x, MIN( COUNTIF({$E$3;$G$3;$I$3;$K$3}, x), COUNTIF({F24;H24;J24;L24}, x) ) ) ) ) -> 1 | N24: Мульти | O24: Мульти | S24: 2-й навык Артуса | U24: С 1 пробуд Люца, база Бертрана
A25: 20 | B25: Исчадия Хаоса | C25: Сид | D25: =IMAGE("https://raw.githubusercontent.com/RedCat161/AoM/main/fiends/fiends4_200.jpg") | E25: ='Созвездия'!B2 | F25: A | G25: ='Созвездия'!B11 | H25: J | I25: ='Созвездия'!B6 | J25: E | K25: ='Созвездия'!B8 | L25: G | M25: =SUM( MAP( UNIQUE({$E$3;$G$3;$I$3;$K$3}), LAMBDA(x, MIN( COUNTIF({$E$3;$G$3;$I$3;$K$3}, x), COUNTIF({F25;H25;J25;L25}, x) ) ) ) ) -> 2
A26: 21 | B26: Исчадия Хаоса | C26: Гул | D26: =IMAGE("https://raw.githubusercontent.com/RedCat161/AoM/main/fiends/fiends5_200.jpg") | E26: ='Созвездия'!B3 | F26: B | G26: ='Созвездия'!B8 | H26: G | I26: ='Созвездия'!B2 | J26: A | K26: ='Созвездия'!B2 | L26: A | M26: =SUM( MAP( UNIQUE({$E$3;$G$3;$I$3;$K$3}), LAMBDA(x, MIN( COUNTIF({$E$3;$G$3;$I$3;$K$3}, x), COUNTIF({F26;H26;J26;L26}, x) ) ) ) ) -> 2 | P26: Мульти
A27: 22 | B27: Исчадия Хаоса | C27: Акед | D27: =IMAGE("https://raw.githubusercontent.com/RedCat161/AoM/main/fiends/fiends6_200.jpg") | E27: ='Созвездия'!B7 | F27: F | G27: ='Созвездия'!B7 | H27: F | I27: ='Созвездия'!B12 | J27: K | K27: ='Созвездия'!B5 | L27: D | M27: =SUM( MAP( UNIQUE({$E$3;$G$3;$I$3;$K$3}), LAMBDA(x, MIN( COUNTIF({$E$3;$G$3;$I$3;$K$3}, x), COUNTIF({F27;H27;J27;L27}, x) ) ) ) ) -> 0
A28: 23 | B28: Исчадия Хаоса | C28: Фурия | D28: =IMAGE("https://raw.githubusercontent.com/RedCat161/AoM/main/fiends/fiends1_200.jpg") | E28: ='Созвездия'!B3 | F28: B | G28: ='Созвездия'!B3 | H28: B | I28: ='Созвездия'!B3 | J28: B | K28: ='Созвездия'!B3 | L28: B | M28: =SUM( MAP( UNIQUE({$E$3;$G$3;$I$3;$K$3}), LAMBDA(x, MIN( COUNTIF({$E$3;$G$3;$I$3;$K$3}, x), COUNTIF({F28;H28;J28;L28}, x) ) ) ) ) -> 1 | N28: Мульти | O28: Мульти | P28: Мульти если есть статика
A29: 24 | B29: Исчадия Хаоса | C29: Луксурия | D29: =IMAGE("https://raw.githubusercontent.com/RedCat161/AoM/main/fiends/fiends7_200.jpg") | E29: ='Созвездия'!B2 | F29: A | G29: ='Созвездия'!B13 | H29: L | I29: ='Созвездия'!B11 | J29: J | K29: ='Созвездия'!B8 | L29: G | M29: =SUM( MAP( UNIQUE({$E$3;$G$3;$I$3;$K$3}), LAMBDA(x, MIN( COUNTIF({$E$3;$G$3;$I$3;$K$3}, x), COUNTIF({F29;H29;J29;L29}, x) ) ) ) ) -> 2
A30: 25 | B30: Исчадия Хаоса | C30: Инвид | D30: =IMAGE("https://raw.githubusercontent.com/RedCat161/AoM/main/fiends/fiends3_200.jpg") | E30: ='Созвездия'!B9 | F30: H | G30: ='Созвездия'!B11 | H30: J | I30: ='Созвездия'!B2 | J30: A | K30: ='Созвездия'!B3 | L30: B | M30: =SUM( MAP( UNIQUE({$E$3;$G$3;$I$3;$K$3}), LAMBDA(x, MIN( COUNTIF({$E$3;$G$3;$I$3;$K$3}, x), COUNTIF({F30;H30;J30;L30}, x) ) ) ) ) -> 1 | P30: Мульти
A31: 26 | B31: Исчадия Хаоса | C31: Суперия | D31: =IMAGE("https://raw.githubusercontent.com/RedCat161/AoM/main/fiends/fiends2_200.jpg") | E31: ='Созвездия'!B2 | F31: A | G31: ='Созвездия'!B2 | H31: A | I31: ='Созвездия'!B6 | J31: E | K31: ='Созвездия'!B8 | L31: G | M31: =SUM( MAP( UNIQUE({$E$3;$G$3;$I$3;$K$3}), LAMBDA(x, MIN( COUNTIF({$E$3;$G$3;$I$3;$K$3}, x), COUNTIF({F31;H31;J31;L31}, x) ) ) ) ) -> 2 | P31: Мульти
A32: 27 | B32: Стражи Порядка | C32: Омфис | D32: =IMAGE("https://raw.githubusercontent.com/RedCat161/AoM/main/guards/guardian4_200.jpg") | E32: ='Созвездия'!B2 | F32: A | G32: ='Созвездия'!B6 | H32: E | I32: ='Созвездия'!B8 | J32: G | K32: ='Созвездия'!B3 | L32: B | M32: =SUM( MAP( UNIQUE({$E$3;$G$3;$I$3;$K$3}), LAMBDA(x, MIN( COUNTIF({$E$3;$G$3;$I$3;$K$3}, x), COUNTIF({F32;H32;J32;L32}, x) ) ) ) ) -> 3 | U32: база Неферы
A33: 28 | B33: Стражи Порядка | C33: Сири | D33: =IMAGE("https://raw.githubusercontent.com/RedCat161/AoM/main/guards/guardian5_200.jpg") | E33: ='Созвездия'!B9 | F33: H | G33: ='Созвездия'!B10 | H33: I | I33: ='Созвездия'!B10 | J33: I | K33: ='Созвездия'!B5 | L33: D | M33: =SUM( MAP( UNIQUE({$E$3;$G$3;$I$3;$K$3}), LAMBDA(x, MIN( COUNTIF({$E$3;$G$3;$I$3;$K$3}, x), COUNTIF({F33;H33;J33;L33}, x) ) ) ) ) -> 0 | N33: Мульти | O33: Мульти | P33: Мульти | R33: пассивка | U33: база Неферы
A34: 29 | B34: Стражи Порядка | C34: Уоррис | D34: =IMAGE("https://raw.githubusercontent.com/RedCat161/AoM/main/guards/guardian7_200.jpg") | E34: ='Созвездия'!B6 | F34: E | G34: ='Созвездия'!B6 | H34: E | I34: ='Созвездия'!B9 | J34: H | K34: ='Созвездия'!B5 | L34: D | M34: =SUM( MAP( UNIQUE({$E$3;$G$3;$I$3;$K$3}), LAMBDA(x, MIN( COUNTIF({$E$3;$G$3;$I$3;$K$3}, x), COUNTIF({F34;H34;J34;L34}, x) ) ) ) ) -> 1 | U34: база Неферы
A35: 30 | B35: Стражи Порядка | C35: Сехмон | D35: =IMAGE("https://raw.githubusercontent.com/RedCat161/AoM/main/guards/guardian3_200.jpg") | E35: ='Созвездия'!B8 | F35: G | G35: ='Созвездия'!B6 | H35: E | I35: ='Созвездия'!B11 | J35: J | K35: ='Созвездия'!B8 | L35: G | M35: =SUM( MAP( UNIQUE({$E$3;$G$3;$I$3;$K$3}), LAMBDA(x, MIN( COUNTIF({$E$3;$G$3;$I$3;$K$3}, x), COUNTIF({F35;H35;J35;L35}, x) ) ) ) ) -> 2 | U35: база Неферы
A36: 31 | B36: Стражи Порядка | C36: Нефера | D36: =IMAGE("https://raw.githubusercontent.com/RedCat161/AoM/main/guards/guardian01_200.jpg") | E36: ='Созвездия'!B2 | F36: A | G36: ='Созвездия'!B6 | H36: E | I36: ='Созвездия'!B8 | J36: G | K36: ='Созвездия'!B9 | L36: H | M36: =SUM( MAP( UNIQUE({$E$3;$G$3;$I$3;$K$3}), LAMBDA(x, MIN( COUNTIF({$E$3;$G$3;$I$3;$K$3}, x), COUNTIF({F36;H36;J36;L36}, x) ) ) ) ) -> 2
A37: 32 | B37: Стражи Порядка | C37: Инпус | D37: =IMAGE("https://raw.githubusercontent.com/RedCat161/AoM/main/guards/guardian2_200.jpg") | E37: ='Созвездия'!B9 | F37: H | G37: ='Созвездия'!B9 | H37: H | I37: ='Созвездия'!B9 | J37: H | K37: ='Созвездия'!B5 | L37: D | M37: =SUM( MAP( UNIQUE({$E$3;$G$3;$I$3;$K$3}), LAMBDA(x, MIN( COUNTIF({$E$3;$G$3;$I$3;$K$3}, x), COUNTIF({F37;H37;J37;L37}, x) ) ) ) ) -> 0 | O37: Мульти | U37: база Неферы
A38: 33 | B38: Стражи Порядка | C38: Скара | D38: =IMAGE("https://raw.githubusercontent.com/RedCat161/AoM/main/guards/guardian6_200.jpg") | E38: ='Созвездия'!B8 | F38: G | G38: ='Созвездия'!B8 | H38: G | I38: ='Созвездия'!B6 | J38: E | K38: ='Созвездия'!B2 | L38: A | M38: =SUM( MAP( UNIQUE({$E$3;$G$3;$I$3;$K$3}), LAMBDA(x, MIN( COUNTIF({$E$3;$G$3;$I$3;$K$3}, x), COUNTIF({F38;H38;J38;L38}, x) ) ) ) ) -> 2 | U38: база Неферы
A39: 34 | B39: Ваны Северных Вершин | C39: Стар'вальд | D39: =IMAGE("https://raw.githubusercontent.com/RedCat161/AoM/main/Van/Van4_200.jpg") | E39: ='Созвездия'!B8 | F39: G | G39: ='Созвездия'!B3 | H39: B | I39: ='Созвездия'!B6 | J39: E | K39: ='Созвездия'!B2 | L39: A | M39: =SUM( MAP( UNIQUE({$E$3;$G$3;$I$3;$K$3}), LAMBDA(x, MIN( COUNTIF({$E$3;$G$3;$I$3;$K$3}, x), COUNTIF({F39;H39;J39;L39}, x) ) ) ) ) -> 3
A40: 35 | B40: Ваны Северных Вершин | C40: Рей'мунд | D40: =IMAGE("https://raw.githubusercontent.com/RedCat161/AoM/main/Van/Van2_200.jpg") | E40: ='Созвездия'!B9 | F40: H | G40: ='Созвездия'!B9 | H40: H | I40: ='Созвездия'!B11 | J40: J | K40: ='Созвездия'!B8 | L40: G | M40: =SUM( MAP( UNIQUE({$E$3;$G$3;$I$3;$K$3}), LAMBDA(x, MIN( COUNTIF({$E$3;$G$3;$I$3;$K$3}, x), COUNTIF({F40;H40;J40;L40}, x) ) ) ) ) -> 1 | O40: Мульти
...

Sheet Созвездия
A1: Буква | B1: Иконка
A2: A | B2: =IMAGE("https://raw.githubusercontent.com/RedCat161/AoM/main/Runes/Rune4_200.jpg")
A3: B | B3: =IMAGE("https://raw.githubusercontent.com/RedCat161/AoM/main/Runes/Rune1_200.jpg") | H3: ='Созвездия'!B2 | I3: ='Созвездия'!B3 | J3: ='Созвездия'!B4 | K3: ='Созвездия'!B5 | L3: ='Созвездия'!B6 | M3: ='Созвездия'!B7 | N3: ='Созвездия'!B8 | O3: ='Созвездия'!B9 | P3: ='Созвездия'!B10 | Q3: ='Созвездия'!B11 | R3: ='Созвездия'!B12 | S3: ='Созвездия'!B13
A4: C | B4: =IMAGE("https://raw.githubusercontent.com/RedCat161/AoM/main/Runes/Rune9_200.jpg") | H4: A | I4: B | J4: C | K4: D | L4: E | M4: F | N4: G | O4: H | P4: I | Q4: J | R4: K | S4: L
A5: D | B5: =IMAGE("https://raw.githubusercontent.com/RedCat161/AoM/main/Runes/Rune5_200.jpg")
A6: E | B6: =IMAGE("https://raw.githubusercontent.com/RedCat161/AoM/main/Runes/Rune3_200.jpg")
A7: F | B7: =IMAGE("https://raw.githubusercontent.com/RedCat161/AoM/main/Runes/Rune2_200.jpg")
A8: G | B8: =IMAGE("https://raw.githubusercontent.com/RedCat161/AoM/main/Runes/Rune10_200.jpg")
A9: H | B9: =IMAGE("https://raw.githubusercontent.com/RedCat161/AoM/main/Runes/Rune11_200.jpg")
A10: I | B10: =IMAGE("https://raw.githubusercontent.com/RedCat161/AoM/main/Runes/Rune6_200.jpg")
A11: J | B11: =IMAGE("https://raw.githubusercontent.com/RedCat161/AoM/main/Runes/Rune7_200.jpg")
A12: K | B12: =IMAGE("https://raw.githubusercontent.com/RedCat161/AoM/main/Runes/Rune12_200.jpg")
A13: L | B13: =IMAGE("https://raw.githubusercontent.com/RedCat161/AoM/main/Runes/Rune8_200.jpg")
